<mujoco model="rohand_right">
    <compiler angle="radian" />
    <asset>
        <mesh name="base_link" content_type="model/stl" file="../assets/meshes_r/base_link.STL"/>
        <mesh name="if_proximal_link" content_type="model/stl" file="../assets/meshes_r/if_proximal_link.STL"/>
        <mesh name="if_distal_link" content_type="model/stl" file="../assets/meshes_r/if_distal_link.STL"/>
        <mesh name="if_connecting_link" content_type="model/stl" file="../assets/meshes_r/if_connecting_link.STL"/>
        <mesh name="mf_proximal_link" content_type="model/stl" file="../assets/meshes_r/mf_proximal_link.STL"/>
        <mesh name="mf_distal_link" content_type="model/stl" file="../assets/meshes_r/mf_distal_link.STL"/>
        <mesh name="mf_connecting_link" content_type="model/stl" file="../assets/meshes_r/mf_connecting_link.STL"/>
        <mesh name="rf_proximal_link" content_type="model/stl" file="../assets/meshes_r/rf_proximal_link.STL"/>
        <mesh name="rf_distal_link" content_type="model/stl" file="../assets/meshes_r/rf_distal_link.STL"/>
        <mesh name="rf_connecting_link" content_type="model/stl" file="../assets/meshes_r/rf_connecting_link.STL"/>
        <mesh name="lf_proximal_link" content_type="model/stl" file="../assets/meshes_r/lf_proximal_link.STL"/>
        <mesh name="lf_distal_link" content_type="model/stl" file="../assets/meshes_r/lf_distal_link.STL"/>
        <mesh name="lf_connecting_link" content_type="model/stl" file="../assets/meshes_r/lf_connecting_link.STL"/>
        <mesh name="th_root_link" content_type="model/stl" file="../assets/meshes_r/th_root_link.STL"/>
        <mesh name="th_slider_connecting_link" content_type="model/stl" file="../assets/meshes_r/th_slider_connecting_link.STL"/>
        <mesh name="th_slider_link" content_type="model/stl" file="../assets/meshes_r/th_slider_link.STL"/>
        <mesh name="th_connecting_link" content_type="model/stl" file="../assets/meshes_r/th_connecting_link.STL"/>
        <mesh name="th_distal_link" content_type="model/stl" file="../assets/meshes_r/th_distal_link.STL"/>
        <mesh name="th_proximal_link" content_type="model/stl" file="../assets/meshes_r/th_proximal_link.STL"/>
    </asset>
    <worldbody>
        <body name="base_link" gravcomp="1">
            <geom type="mesh" rgba="0.776471 0.756863 0.737255 1" mesh="base_link"/>
        </body>
        <body name="th_root_link" pos="0.0490826 0.0198778 -0.0230224" quat="0.994021 0.000704684 0.108993 0.00642674" gravcomp="1">
            <inertial pos="0.00191984 0.00319719 -0.00597433" quat="-0.195508 0.354122 0.316551 -0.858004" mass="0.017482" diaginertia="2.15824e-06 1.78948e-06 8.42171e-07"/>
            <joint name="th_root_link" pos="0 0 0" axis="-1 0 0" range="0 1.57" ref="0.7" damping="0.05"/>
            <geom type="mesh" rgba="0.776471 0.756863 0.737255 1" mesh="th_root_link"/>
            <body name="th_slider_connecting_link" pos="0.0150163 0.00377111 -0.0184123" quat="0.655201 -0.265917 -0.659812 0.254261" gravcomp="1">
                <inertial pos="-0.00809998 0.00382843 -0.00282376" quat="0.892632 0.450786 0 0" mass="0.000789049" diaginertia="1.19393e-08 1.07536e-08 1.35034e-09"/>
                <joint name="th_slider_connecting_link" pos="0 0 0" axis="-1 0 0" range="0.0 1.0" ref="0.75" damping="0.03"/>
                <geom type="mesh" rgba="0.776471 0.756863 0.737255 1" mesh="th_slider_connecting_link"/>
                <body name="th_slider_link" pos="0 0.00883641 -0.00651754" gravcomp="1">
                    <inertial pos="-0.00804903 0.00193436 -0.00890089" quat="0.702987 0.0761563 0.0761476 -0.703002" mass="0.0752752" diaginertia="6.05507e-08 4.65637e-08 1.9027e-08"/>
                    <joint name="th_slider_link" pos="0 0 0" axis="-1 0 0" damping="0.05"/>
                    <geom type="mesh" rgba="0.776471 0.756863 0.737255 1" mesh="th_slider_link"/>
                    <body name="th_connecting_link" pos="0.00440345 0.0076881 -0.0314156" quat="0.803914 0.594745 0 0" gravcomp="1">
                        <inertial pos="-0.00373227 -0.00464828 -0.00091513" quat="0.467303 0.530686 0.530686 -0.467303" mass="0.0261208" diaginertia="4.35995e-09 3.91261e-09 1.67325e-09"/>
                        <joint name="th_connecting_link" pos="0 0 0" axis="-1 0 0" damping="0.05"/>
                        <geom type="mesh" rgba="0.776471 0.756863 0.737255 1" mesh="th_connecting_link"/>
                        <body name="th_distal_link" pos="-0.00295 -0.00981212 -0.00131618" gravcomp="1">
                            <inertial pos="-0.00665584 -0.0101877 0.00658848" quat="0.453258 0.54272 0.542731 -0.453272" mass="0.1860659" diaginertia="2.36983e-05 1.85862e-05 1.2918e-05"/>
                            <joint name="th_distal_link" pos="0 0 0" axis="-1 0 0"/>
                            <geom type="mesh" rgba="0.776471 0.756863 0.737255 1" mesh="th_distal_link"/>
                        </body>
                    </body>
                    <body name="th_proximal_link" pos="0.00394993 0.000195499 0.0109735" quat="0.678228 -0.200017 -0.628683 -0.323663" gravcomp="1">
                        <inertial pos="0.0113547 -0.000312971 -0.00565436" quat="-0.175069 0.696448 0.301544 -0.627202" mass="0.0704476" diaginertia="2.20935e-04 2.05412e-04 6.20846e-05"/>
                        <joint name="th_proximal_link" pos="0 0 0" axis="-1 0 0" type="slide" damping="0.5"/>
                        <geom type="mesh" rgba="0.776471 0.756863 0.737255 1" mesh="th_proximal_link"/>
                    </body>
                </body>
            </body>
        </body>
        <body name="if_proximal_link" pos="0.115122 0.0375536 0.0020566" quat="0.295459 0.609378 0.687604 0.261846" gravcomp="1">
            <inertial pos="0.0070298 0.00894962 0.0163319" quat="0.662849 -0.246153 -0.246091 -0.662933" mass="0.0152443" diaginertia="1.5138e-06 1.35281e-06 5.40981e-07"/>
            <joint name="if_proximal_link" pos="0 0 0" axis="1 0 0" ref="0.1" damping="0.03"/>
            <geom type="mesh" rgba="0.776471 0.756863 0.737255 1" mesh="if_proximal_link"/>
            <body name="if_distal_link" pos="0 0.021096 0.029073" gravcomp="1">
                <inertial pos="0.00697876 0.0067486 0.0235874" quat="0.700497 -0.0949982 -0.0951152 -0.70088" mass="0.0342358" diaginertia="5.2505e-06 5.24298e-06 5.95152e-07"/>
                <joint name="if_distal_link" pos="0 0 0" axis="1 0 0" damping="0.01"/>
                <geom type="mesh" rgba="0.776471 0.756863 0.737255 1" mesh="if_distal_link"/>
            </body>
        </body>
        <body name="if_connecting_link" pos="0.122756 0.0353019 0.0067253" quat="0.295636 0.609335 0.687498 0.262025" gravcomp="1">
            <inertial pos="0.00370009 0.00341586 0.0165511" quat="0.701491 -0.0889417 -0.0889417 -0.701491" mass="0.00267235" diaginertia="4.96063e-07 4.86522e-07 1.90482e-08"/>
            <joint name="if_connecting_link" pos="0 0 0" axis="1 0 0"/>
            <geom type="mesh" rgba="0.776471 0.756863 0.737255 1" mesh="if_connecting_link"/>
        </body>
        <body name="mf_proximal_link" pos="0.11888 0.01765 0.0069653" quat="0.00334089 0.702842 0.71133 0.00330105" gravcomp="1">
            <inertial pos="0.0070074 0.0203658 0.00677331" quat="0.466516 0.531416 0.531075 -0.466818" mass="0.0182531" diaginertia="2.54837e-06 2.38777e-06 6.77106e-07"/>
            <joint name="mf_proximal_link" pos="0 0 0" axis="1 0 0" ref="0.1" damping="0.03"/>
            <geom type="mesh" rgba="0.776471 0.756863 0.737255 1" mesh="mf_proximal_link"/>
            <body name="mf_distal_link" pos="0 0.040241 0.0078924" gravcomp="1">
                <inertial pos="0.00693657 0.0214322 0.0119471" quat="0.355221 0.611869 0.610762 -0.355534" mass="0.0342357" diaginertia="5.2505e-06 5.24298e-06 5.95151e-07"/>
                <joint name="mf_distal_link" pos="0 0 0" axis="1 0 0" damping="0.01"/>
                <geom type="mesh" rgba="0.776471 0.756863 0.737255 1" mesh="mf_distal_link"/>
            </body>
        </body>
        <body name="mf_connecting_link" pos="0.126338 0.0144304 0.0113662" quat="0.000565756 -0.702408 -0.711774 0.000558312" gravcomp="1">
            <inertial pos="0.00370005 0.0163936 0.0102722" quat="0.357408 0.610131 0.610131 -0.357408" mass="0.00285033" diaginertia="6.82745e-07 6.72641e-07 2.02362e-08"/>
            <joint name="mf_connecting_link" pos="0 0 0" axis="1 0 0"/>
            <geom type="mesh" rgba="0.776471 0.756863 0.737255 1" mesh="mf_connecting_link"/>
        </body>
        <body name="rf_proximal_link" pos="0.11663 -0.002443 0.0062162" quat="0.726796 -4.00974e-05 -3.78937e-05 0.686853" gravcomp="1">
            <inertial pos="0.00704135 -0.0178884 -0.0046376" quat="0.483953 0.515519 0.515557 -0.483973" mass="0.0151473" diaginertia="1.51374e-06 1.35267e-06 5.40891e-07"/>
            <joint name="rf_proximal_link" pos="0 0 0" axis="1 0 0" ref="0.1" damping="0.03"/>
            <geom type="mesh" rgba="0.776471 0.756863 0.737255 1" mesh="rf_proximal_link"/>
            <body name="rf_distal_link" pos="0 -0.035592 -0.0048427" gravcomp="1">
                <inertial pos="0.00697877 -0.0217085 -0.0114017" quat="0.3627 0.606553 0.607179 -0.363148" mass="0.0342355" diaginertia="5.25042e-06 5.2429e-06 5.95154e-07"/>
                <joint name="rf_distal_link" pos="0 0 0" axis="1 0 0" damping="0.01"/>
                <geom type="mesh" rgba="0.776471 0.756863 0.737255 1" mesh="rf_distal_link"/>
            </body>
        </body>
        <body name="rf_connecting_link" pos="0.123853 -0.00613089 0.0106155" quat="0.726833 -0.0001276 -0.000135035 0.686814" gravcomp="1">
            <inertial pos="0.00370009 -0.0143262 -0.00896467" quat="0.357577 0.610032 0.610032 -0.357577" mass="0.00267235" diaginertia="4.96063e-07 4.86522e-07 1.90482e-08"/>
            <joint name="rf_connecting_link" pos="0 0 0" axis="1 0 0"/>
            <geom type="mesh" rgba="0.776471 0.756863 0.737255 1" mesh="rf_connecting_link"/>
        </body>
        <body name="lf_proximal_link" pos="0.11331 -0.022575 0.0042735" quat="0.719041 -0.204609 -0.237125 0.620393" gravcomp="1">
            <inertial pos="0.00699992 -0.0101266 -0.01254" quat="0.289166 0.645275 0.645279 -0.289168" mass="0.0142656" diaginertia="1.53678e-06 1.36656e-06 5.17078e-07"/>
            <joint name="lf_proximal_link" pos="0 0 0" axis="1 0 0" ref="0.1" damping="0.03"/>
            <geom type="mesh" rgba="0.776471 0.756863 0.737255 1" mesh="lf_proximal_link"/>
            <body name="lf_distal_link" pos="0 -0.022718 -0.022439" gravcomp="1">
                <inertial pos="0.00705269 -0.00763281 -0.0155353" quat="0.690987 -0.150197 -0.15019 -0.690956" mass="0.0202843" diaginertia="1.52435e-06 1.4952e-06 3.06212e-07"/>
                <joint name="lf_distal_link" pos="0 0 0" axis="1 0 0" damping="0.01"/>
                <geom type="mesh" rgba="0.776471 0.756863 0.737255 1" mesh="lf_distal_link"/>
            </body>
        </body>
        <body name="lf_connecting_link" pos="0.12024 -0.027096 0.0083686" quat="0.719041 -0.204609 -0.237125 0.620393" gravcomp="1">
            <inertial pos="0.00370001 -0.00492796 -0.0142868" quat="0.694427 -0.13331 -0.13331 -0.694427" mass="0.00247299" diaginertia="3.87303e-07 3.78315e-07 1.76363e-08"/>
            <joint name="lf_connecting_link" pos="0 0 0" axis="1 0 0"/>
            <geom type="mesh" rgba="0.776471 0.756863 0.737255 1" mesh="lf_connecting_link"/>
        </body>
    </worldbody>
    <contact>
        <exclude body1="base_link" body2="if_proximal_link"/>
        <exclude body1="base_link" body2="if_distal_link"/>
        <exclude body1="base_link" body2="if_connecting_link"/>
        <exclude body1="if_connecting_link" body2="if_proximal_link"/>
        <exclude body1="if_connecting_link" body2="if_distal_link"/>
        <exclude body1="if_proximal_link" body2="if_distal_link"/>
        <exclude body1="base_link" body2="mf_proximal_link"/>
        <exclude body1="base_link" body2="mf_distal_link"/>
        <exclude body1="base_link" body2="mf_connecting_link"/>
        <exclude body1="mf_connecting_link" body2="mf_proximal_link"/>
        <exclude body1="mf_connecting_link" body2="mf_distal_link"/>
        <exclude body1="mf_proximal_link" body2="mf_distal_link"/>
        <exclude body1="base_link" body2="rf_proximal_link"/>
        <exclude body1="base_link" body2="rf_distal_link"/>
        <exclude body1="base_link" body2="rf_connecting_link"/>
        <exclude body1="rf_connecting_link" body2="rf_proximal_link"/>
        <exclude body1="rf_connecting_link" body2="rf_distal_link"/>
        <exclude body1="rf_proximal_link" body2="rf_distal_link"/>
        <exclude body1="base_link" body2="lf_proximal_link"/>
        <exclude body1="base_link" body2="lf_connecting_link"/>
        <exclude body1="lf_proximal_link" body2="lf_distal_link"/>
        <exclude body1="lf_connecting_link" body2="lf_proximal_link"/>
        <exclude body1="lf_connecting_link" body2="lf_distal_link"/>
        <exclude body1="base_link" body2="th_root_link"/>
        <exclude body1="th_root_link" body2="base_link"/>
        <exclude body1="th_root_link" body2="th_slider_connecting_link"/>
        <exclude body1="th_root_link" body2="th_slider_link"/>
        <exclude body1="th_root_link" body2="th_connecting_link"/>
        <exclude body1="th_root_link" body2="th_distal_link"/>
        <exclude body1="th_root_link" body2="th_proximal_link"/>
        <exclude body1="th_slider_connecting_link" body2="base_link"/>
        <exclude body1="th_slider_connecting_link" body2="th_slider_link"/>
        <exclude body1="th_slider_connecting_link" body2="th_connecting_link"/>
        <exclude body1="th_slider_connecting_link" body2="th_distal_link"/>
        <exclude body1="th_slider_connecting_link" body2="th_proximal_link"/>
        <exclude body1="th_slider_link" body2="base_link"/>
        <exclude body1="th_slider_link" body2="th_connecting_link"/>
        <exclude body1="th_slider_link" body2="th_distal_link"/>
        <exclude body1="th_slider_link" body2="th_proximal_link"/>
        <exclude body1="th_connecting_link" body2="base_link"/>
        <exclude body1="th_connecting_link" body2="th_distal_link"/>
        <exclude body1="th_connecting_link" body2="th_proximal_link"/>
        <exclude body1="th_distal_link" body2="base_link"/>
        <exclude body1="th_distal_link" body2="th_proximal_link"/>
        <exclude body1="th_proximal_link" body2="base_link"/>
    </contact>
    <equality>
        <connect body1="if_distal_link" body2="if_connecting_link" anchor="-0.00328 -0.00436 0.00634" solimp="0.95 0.99 0.001" solref="0.005 1"/>
        <connect body1="mf_distal_link" body2="mf_connecting_link" anchor="-0.00326 0.00138 0.00756" solimp="0.95 0.99 0.001" solref="0.005 1"/>
        <connect body1="rf_distal_link" body2="rf_connecting_link" anchor="-0.00328 -0.00157 -0.00753" solimp="0.95 0.99 0.001" solref="0.005 1"/>
        <connect body1="lf_distal_link" body2="lf_connecting_link" anchor="-0.00330 0.00266 -0.00704" solimp="0.95 0.99 0.001" solref="0.005 1"/>
        <connect body1="th_proximal_link" body2="th_root_link" anchor="0.0046 -0.0055 0.002" solimp="0.95 0.99 0.001" solref="0.005 1"/>
        <connect body1="th_distal_link" body2="th_proximal_link" anchor="0 0.00027 0.0113" solimp="0.8 0.95 0.001" solref="0.005 1"/>
    </equality>
    <actuator>
        <position name="index_finger" joint="if_proximal_link" kp="1" ctrlrange="0 1.44"/>
        <position name="middle_finger" joint="mf_proximal_link" kp="1" ctrlrange="0 1.44"/>
        <position name="ring_finger" joint="rf_proximal_link" kp="1" ctrlrange="0 1.44"/>
        <position name="little_finger" joint="lf_proximal_link" kp="1" ctrlrange="0 1.44"/>
        <position name="thumb_root" joint="th_root_link" kp="1" ctrlrange="0 1.57"/>
        <position name="thumb" joint="th_slider_connecting_link" kp="1" ctrlrange="0.0 1.0"/>
    </actuator>
</mujoco>